<?xml version="1.0" ?>
<!-- =================================================================================== -->
<!-- |    This document was autogenerated by xacro from /home/zeng/arti4/src/arti_description/urdf/section_A_assembly.xacro | -->
<!-- |    EDITING THIS FILE BY HAND IS NOT RECOMMENDED                                 | -->
<!-- =================================================================================== -->
<!-- This is the Section A assembly file -->
<sdf version="1.5" xmlns:xacro="http://ros.org/wiki/xacro">
  <model name="section_A_assembly">
    <!-- Some Constants -->
    <!-- Wheel Properties -->
    <!-- Section A Size -->
    <!-- wheel position -->
    <!-- Section A -->
    <link name="section_A">
      <!-- <pose frame=''>0 0 0.05 0 -0 0</pose> -->
      <pose>0 0 0.06 0 0 0</pose>
      <inertial>
        <mass>1</mass>
        <inertia>
          <ixx>0.166667</ixx>
          <ixy>0</ixy>
          <ixz>0</ixz>
          <iyy>0.166667</iyy>
          <iyz>0</iyz>
          <izz>0.166667</izz>
        </inertia>
        <pose frame="">0 0 0 0 -0 0</pose>
      </inertial>
      <self_collide>0</self_collide>
      <kinematic>0</kinematic>
      <gravity>1</gravity>
      <visual name="visual">
        <geometry>
          <box>
            <size>0.5 0.3 0.1</size>
          </box>
        </geometry>
        <material>
          <script>
            <name>Gazebo/Grey</name>
            <uri>file://media/materials/scripts/gazebo.material</uri>
          </script>
          <ambient>0.3 0.3 0.3 1</ambient>
          <diffuse>0.7 0.7 0.7 1</diffuse>
          <specular>0.01 0.01 0.01 1</specular>
          <emissive>0 0 0 1</emissive>
          <shader type="vertex">
            <normal_map>__default__</normal_map>
          </shader>
        </material>
        <pose frame="">0 0 0 0 -0 0</pose>
        <cast_shadows>1</cast_shadows>
        <transparency>0</transparency>
      </visual>
      <collision name="collision">
        <laser_retro>0</laser_retro>
        <max_contacts>10</max_contacts>
        <pose frame="">0 0 0 0 -0 0</pose>
        <geometry>
          <box>
            <!-- <size>0.3 0.2 0.1</size> -->
            <size>0.5 0.3 0.1</size>
          </box>
        </geometry>
      </collision>
    </link>
    <!-- All four wheels -->
    <link name="front_left_wheel_link">
      <pose>0.15 0.165 0.019209 1.570795 0 3.14159</pose>
      <gravity>1</gravity>
      <self_collide>1</self_collide>
      <kinematic>0</kinematic>
      <inertial>
        <mass>1</mass>
        <inertia>
          <ixx>1</ixx>
          <ixy>0</ixy>
          <ixz>0</ixz>
          <iyy>1</iyy>
          <iyz>0</iyz>
          <izz>1</izz>
        </inertia>
      </inertial>
      <visual name="visual">
        <pose frame="">-0.0375 -0.0375 -0.034 0 0 0</pose>
        <geometry>
          <mesh>
            <uri>model://track_drum/meshes/drum.STL</uri>
            <scale>0.001 0.001 0.001</scale>
          </mesh>
        </geometry>
        <material>
          <lighting>1</lighting>
          <script>
            <uri>file://media/materials/scripts/gazebo.material</uri>
            <name>Gazebo/Grey</name>
          </script>
          <ambient>0.3 0.3 0.3 1</ambient>
          <diffuse>0.7 0.7 0.7 1</diffuse>
          <specular>0.01 0.01 0.01 1</specular>
          <emissive>0 0 0 1</emissive>
          <shader type="vertex">
            <normal_map>__default__</normal_map>
          </shader>
        </material>
        <cast_shadows>1</cast_shadows>
        <transparency>0</transparency>
      </visual>
      <collision name="collision">
        <laser_retro>0</laser_retro>
        <max_contacts>20</max_contacts>
        <!-- <pose frame=''>-0.0375 -0.0375 -0.034 0 -0 0</pose> -->
        <geometry>
          <cylinder>
            <radius>0.038418</radius>
            <length>0.03</length>
          </cylinder>
        </geometry>
        <surface>
          <friction>
            <ode>
              <mu>1</mu>
              <mu2>1</mu2>
              <fdir1>0 0 0</fdir1>
              <slip1>0</slip1>
              <slip2>0</slip2>
            </ode>
          </friction>
          <bounce>
            <restitution_coefficient>0</restitution_coefficient>
            <threshold>1</threshold>
          </bounce>
          <contact>
            <collide_without_contact>0</collide_without_contact>
            <collide_without_contact_bitmask>1</collide_without_contact_bitmask>
            <collide_bitmask>1</collide_bitmask>
            <ode>
              <soft_cfm>0.1</soft_cfm>
              <soft_erp>0.2</soft_erp>
              <kp>1e+13</kp>
              <kd>1</kd>
              <max_vel>0.01</max_vel>
              <min_depth>0</min_depth>
            </ode>
            <bullet>
              <split_impulse>1</split_impulse>
              <split_impulse_penetration_threshold>-0.01</split_impulse_penetration_threshold>
              <soft_cfm>0</soft_cfm>
              <soft_erp>0.2</soft_erp>
              <kp>1e+13</kp>
              <kd>1</kd>
            </bullet>
          </contact>
        </surface>
      </collision>
    </link>
    <link name="front_left_damping_link">
      <pose>0.15 0.165 0.019209 1.570795 0 3.14159</pose>
    </link>
    <joint name="front_left_wheel_revolute" type="revolute">
      <pose>0 0 0 0 0 0</pose>
      <child>front_left_wheel_link</child>
      <parent>front_left_damping_link</parent>
      <axis>
        <xyz>0 0 1</xyz>
      </axis>
    </joint>
    <joint name="front_left_wheel_damping" type="prismatic">
      <pose>0 0 -0.015 0 0 0</pose>
      <child>front_left_damping_link</child>
      <parent>section_A</parent>
      <axis>
        <xyz>0 1 0</xyz>
        <dynamics>
          <damping>0.1</damping>
          <spring_stiffness>10</spring_stiffness>
        </dynamics>
        <limit>
          <upper>0.001</upper>
          <lower>-0.001</lower>
        </limit>
      </axis>
    </joint>
    <link name="front_right_wheel_link">
      <pose> 0.15 -0.165 0.019209 1.570795 0 0 </pose>
      <gravity>1</gravity>
      <self_collide>1</self_collide>
      <kinematic>0</kinematic>
      <inertial>
        <mass>1</mass>
        <inertia>
          <ixx>1</ixx>
          <ixy>0</ixy>
          <ixz>0</ixz>
          <iyy>1</iyy>
          <iyz>0</iyz>
          <izz>1</izz>
        </inertia>
      </inertial>
      <visual name="visual">
        <pose frame="">-0.0375 -0.0375 -0.034 0 0 0</pose>
        <geometry>
          <mesh>
            <uri>model://track_drum/meshes/drum.STL</uri>
            <scale>0.001 0.001 0.001</scale>
          </mesh>
        </geometry>
        <material>
          <lighting>1</lighting>
          <script>
            <uri>file://media/materials/scripts/gazebo.material</uri>
            <name>Gazebo/Grey</name>
          </script>
          <ambient>0.3 0.3 0.3 1</ambient>
          <diffuse>0.7 0.7 0.7 1</diffuse>
          <specular>0.01 0.01 0.01 1</specular>
          <emissive>0 0 0 1</emissive>
          <shader type="vertex">
            <normal_map>__default__</normal_map>
          </shader>
        </material>
        <cast_shadows>1</cast_shadows>
        <transparency>0</transparency>
      </visual>
      <collision name="collision">
        <laser_retro>0</laser_retro>
        <max_contacts>20</max_contacts>
        <!-- <pose frame=''>-0.0375 -0.0375 -0.034 0 -0 0</pose> -->
        <geometry>
          <cylinder>
            <radius>0.038418</radius>
            <length>0.03</length>
          </cylinder>
        </geometry>
        <surface>
          <friction>
            <ode>
              <mu>1</mu>
              <mu2>1</mu2>
              <fdir1>0 0 0</fdir1>
              <slip1>0</slip1>
              <slip2>0</slip2>
            </ode>
          </friction>
          <bounce>
            <restitution_coefficient>0</restitution_coefficient>
            <threshold>1</threshold>
          </bounce>
          <contact>
            <collide_without_contact>0</collide_without_contact>
            <collide_without_contact_bitmask>1</collide_without_contact_bitmask>
            <collide_bitmask>1</collide_bitmask>
            <ode>
              <soft_cfm>0.1</soft_cfm>
              <soft_erp>0.2</soft_erp>
              <kp>1e+13</kp>
              <kd>1</kd>
              <max_vel>0.01</max_vel>
              <min_depth>0</min_depth>
            </ode>
            <bullet>
              <split_impulse>1</split_impulse>
              <split_impulse_penetration_threshold>-0.01</split_impulse_penetration_threshold>
              <soft_cfm>0</soft_cfm>
              <soft_erp>0.2</soft_erp>
              <kp>1e+13</kp>
              <kd>1</kd>
            </bullet>
          </contact>
        </surface>
      </collision>
    </link>
    <link name="front_right_damping_link">
      <pose> 0.15 -0.165 0.019209 1.570795 0 0 </pose>
    </link>
    <joint name="front_right_wheel_revolute" type="revolute">
      <pose>0 0 0 0 0 0</pose>
      <child>front_right_wheel_link</child>
      <parent>front_right_damping_link</parent>
      <axis>
        <xyz>0 0 1</xyz>
      </axis>
    </joint>
    <joint name="front_right_wheel_damping" type="prismatic">
      <pose>0 0 -0.015 0 0 0</pose>
      <child>front_right_damping_link</child>
      <parent>section_A</parent>
      <axis>
        <xyz>0 1 0</xyz>
        <dynamics>
          <damping>0.1</damping>
          <spring_stiffness>10</spring_stiffness>
        </dynamics>
        <limit>
          <upper>0.001</upper>
          <lower>-0.001</lower>
        </limit>
      </axis>
    </joint>
    <link name="rear_left_wheel_link">
      <pose> -0.15 0.165 0.019209 1.570795 0 3.14159</pose>
      <gravity>1</gravity>
      <self_collide>1</self_collide>
      <kinematic>0</kinematic>
      <inertial>
        <mass>1</mass>
        <inertia>
          <ixx>1</ixx>
          <ixy>0</ixy>
          <ixz>0</ixz>
          <iyy>1</iyy>
          <iyz>0</iyz>
          <izz>1</izz>
        </inertia>
      </inertial>
      <visual name="visual">
        <pose frame="">-0.0375 -0.0375 -0.034 0 0 0</pose>
        <geometry>
          <mesh>
            <uri>model://track_drum/meshes/drum.STL</uri>
            <scale>0.001 0.001 0.001</scale>
          </mesh>
        </geometry>
        <material>
          <lighting>1</lighting>
          <script>
            <uri>file://media/materials/scripts/gazebo.material</uri>
            <name>Gazebo/Grey</name>
          </script>
          <ambient>0.3 0.3 0.3 1</ambient>
          <diffuse>0.7 0.7 0.7 1</diffuse>
          <specular>0.01 0.01 0.01 1</specular>
          <emissive>0 0 0 1</emissive>
          <shader type="vertex">
            <normal_map>__default__</normal_map>
          </shader>
        </material>
        <cast_shadows>1</cast_shadows>
        <transparency>0</transparency>
      </visual>
      <collision name="collision">
        <laser_retro>0</laser_retro>
        <max_contacts>20</max_contacts>
        <!-- <pose frame=''>-0.0375 -0.0375 -0.034 0 -0 0</pose> -->
        <geometry>
          <cylinder>
            <radius>0.038418</radius>
            <length>0.03</length>
          </cylinder>
        </geometry>
        <surface>
          <friction>
            <ode>
              <mu>1</mu>
              <mu2>1</mu2>
              <fdir1>0 0 0</fdir1>
              <slip1>0</slip1>
              <slip2>0</slip2>
            </ode>
          </friction>
          <bounce>
            <restitution_coefficient>0</restitution_coefficient>
            <threshold>1</threshold>
          </bounce>
          <contact>
            <collide_without_contact>0</collide_without_contact>
            <collide_without_contact_bitmask>1</collide_without_contact_bitmask>
            <collide_bitmask>1</collide_bitmask>
            <ode>
              <soft_cfm>0.1</soft_cfm>
              <soft_erp>0.2</soft_erp>
              <kp>1e+13</kp>
              <kd>1</kd>
              <max_vel>0.01</max_vel>
              <min_depth>0</min_depth>
            </ode>
            <bullet>
              <split_impulse>1</split_impulse>
              <split_impulse_penetration_threshold>-0.01</split_impulse_penetration_threshold>
              <soft_cfm>0</soft_cfm>
              <soft_erp>0.2</soft_erp>
              <kp>1e+13</kp>
              <kd>1</kd>
            </bullet>
          </contact>
        </surface>
      </collision>
    </link>
    <link name="rear_left_damping_link">
      <pose> -0.15 0.165 0.019209 1.570795 0 3.14159</pose>
    </link>
    <joint name="rear_left_wheel_revolute" type="revolute">
      <pose>0 0 0 0 0 0</pose>
      <child>rear_left_wheel_link</child>
      <parent>rear_left_damping_link</parent>
      <axis>
        <xyz>0 0 1</xyz>
      </axis>
    </joint>
    <joint name="rear_left_wheel_damping" type="prismatic">
      <pose>0 0 -0.015 0 0 0</pose>
      <child>rear_left_damping_link</child>
      <parent>section_A</parent>
      <axis>
        <xyz>0 1 0</xyz>
        <dynamics>
          <damping>0.1</damping>
          <spring_stiffness>10</spring_stiffness>
        </dynamics>
        <limit>
          <upper>0.001</upper>
          <lower>-0.001</lower>
        </limit>
      </axis>
    </joint>
    <link name="rear_right_wheel_link">
      <pose> -0.15 -0.165 0.019209 1.570795 0 0 </pose>
      <gravity>1</gravity>
      <self_collide>1</self_collide>
      <kinematic>0</kinematic>
      <inertial>
        <mass>1</mass>
        <inertia>
          <ixx>1</ixx>
          <ixy>0</ixy>
          <ixz>0</ixz>
          <iyy>1</iyy>
          <iyz>0</iyz>
          <izz>1</izz>
        </inertia>
      </inertial>
      <visual name="visual">
        <pose frame="">-0.0375 -0.0375 -0.034 0 0 0</pose>
        <geometry>
          <mesh>
            <uri>model://track_drum/meshes/drum.STL</uri>
            <scale>0.001 0.001 0.001</scale>
          </mesh>
        </geometry>
        <material>
          <lighting>1</lighting>
          <script>
            <uri>file://media/materials/scripts/gazebo.material</uri>
            <name>Gazebo/Grey</name>
          </script>
          <ambient>0.3 0.3 0.3 1</ambient>
          <diffuse>0.7 0.7 0.7 1</diffuse>
          <specular>0.01 0.01 0.01 1</specular>
          <emissive>0 0 0 1</emissive>
          <shader type="vertex">
            <normal_map>__default__</normal_map>
          </shader>
        </material>
        <cast_shadows>1</cast_shadows>
        <transparency>0</transparency>
      </visual>
      <collision name="collision">
        <laser_retro>0</laser_retro>
        <max_contacts>20</max_contacts>
        <!-- <pose frame=''>-0.0375 -0.0375 -0.034 0 -0 0</pose> -->
        <geometry>
          <cylinder>
            <radius>0.038418</radius>
            <length>0.03</length>
          </cylinder>
        </geometry>
        <surface>
          <friction>
            <ode>
              <mu>1</mu>
              <mu2>1</mu2>
              <fdir1>0 0 0</fdir1>
              <slip1>0</slip1>
              <slip2>0</slip2>
            </ode>
          </friction>
          <bounce>
            <restitution_coefficient>0</restitution_coefficient>
            <threshold>1</threshold>
          </bounce>
          <contact>
            <collide_without_contact>0</collide_without_contact>
            <collide_without_contact_bitmask>1</collide_without_contact_bitmask>
            <collide_bitmask>1</collide_bitmask>
            <ode>
              <soft_cfm>0.1</soft_cfm>
              <soft_erp>0.2</soft_erp>
              <kp>1e+13</kp>
              <kd>1</kd>
              <max_vel>0.01</max_vel>
              <min_depth>0</min_depth>
            </ode>
            <bullet>
              <split_impulse>1</split_impulse>
              <split_impulse_penetration_threshold>-0.01</split_impulse_penetration_threshold>
              <soft_cfm>0</soft_cfm>
              <soft_erp>0.2</soft_erp>
              <kp>1e+13</kp>
              <kd>1</kd>
            </bullet>
          </contact>
        </surface>
      </collision>
    </link>
    <link name="rear_right_damping_link">
      <pose> -0.15 -0.165 0.019209 1.570795 0 0 </pose>
    </link>
    <joint name="rear_right_wheel_revolute" type="revolute">
      <pose>0 0 0 0 0 0</pose>
      <child>rear_right_wheel_link</child>
      <parent>rear_right_damping_link</parent>
      <axis>
        <xyz>0 0 1</xyz>
      </axis>
    </joint>
    <joint name="rear_right_wheel_damping" type="prismatic">
      <pose>0 0 -0.015 0 0 0</pose>
      <child>rear_right_damping_link</child>
      <parent>section_A</parent>
      <axis>
        <xyz>0 1 0</xyz>
        <dynamics>
          <damping>0.1</damping>
          <spring_stiffness>10</spring_stiffness>
        </dynamics>
        <limit>
          <upper>0.001</upper>
          <lower>-0.001</lower>
        </limit>
      </axis>
    </joint>
    <!-- Track Block Properties -->
    <!-- Left Track Block -->
    <link name="section_A_left_block">
      <pose>0 0.19 0.06 0 0 0</pose>
      <inertial>
        <mass>1</mass>
        <inertia>
          <ixx>0.166667</ixx>
          <ixy>0</ixy>
          <ixz>0</ixz>
          <iyy>0.166667</iyy>
          <iyz>0</iyz>
          <izz>0.166667</izz>
        </inertia>
        <pose>0 0 0 0 -0 0</pose>
      </inertial>
      <self_collide>0</self_collide>
      <kinematic>0</kinematic>
      <gravity>1</gravity>
      <!--   <visual name='visual'>
    <geometry>
      <box>
        <xacro:insert_block name="body_size"/>
      </box>
    </geometry>
    <material>
      <script>
        <name>Gazebo/Grey</name>
        <uri>file://media/materials/scripts/gazebo.material</uri>
      </script>
      <ambient>0.3 0.3 0.3 1</ambient>
      <diffuse>0.7 0.7 0.7 1</diffuse>
      <specular>0.01 0.01 0.01 1</specular>
      <emissive>0 0 0 1</emissive>
      <shader type='vertex'>
        <normal_map>__default__</normal_map>
      </shader>
    </material>
    <pose frame=''>0 0 0 0 -0 0</pose>
    <cast_shadows>1</cast_shadows>
    <transparency>0</transparency>
  </visual> -->
      <collision name="collision">
        <laser_retro>0</laser_retro>
        <max_contacts>10</max_contacts>
        <pose>0 0 0 0 -0 0</pose>
        <geometry>
          <box>
            <size>0.5 0.001 0.1</size>
          </box>
        </geometry>
      </collision>
    </link>
    <joint name="section_A_left_block_joint" type="fixed">
      <pose>0 0 0 0 0 0</pose>
      <child>section_A_left_block</child>
      <parent>section_A</parent>
    </joint>
    <!-- Right Track Block-->
    <link name="section_A_right_block">
      <pose>0 -0.19 0.06 0 0 0</pose>
      <inertial>
        <mass>1</mass>
        <inertia>
          <ixx>0.166667</ixx>
          <ixy>0</ixy>
          <ixz>0</ixz>
          <iyy>0.166667</iyy>
          <iyz>0</iyz>
          <izz>0.166667</izz>
        </inertia>
        <pose>0 0 0 0 -0 0</pose>
      </inertial>
      <self_collide>0</self_collide>
      <kinematic>0</kinematic>
      <gravity>1</gravity>
      <!--   <visual name='visual'>
    <geometry>
      <box>
        <xacro:insert_block name="body_size"/>
      </box>
    </geometry>
    <material>
      <script>
        <name>Gazebo/Grey</name>
        <uri>file://media/materials/scripts/gazebo.material</uri>
      </script>
      <ambient>0.3 0.3 0.3 1</ambient>
      <diffuse>0.7 0.7 0.7 1</diffuse>
      <specular>0.01 0.01 0.01 1</specular>
      <emissive>0 0 0 1</emissive>
      <shader type='vertex'>
        <normal_map>__default__</normal_map>
      </shader>
    </material>
    <pose frame=''>0 0 0 0 -0 0</pose>
    <cast_shadows>1</cast_shadows>
    <transparency>0</transparency>
  </visual> -->
      <collision name="collision">
        <laser_retro>0</laser_retro>
        <max_contacts>10</max_contacts>
        <pose>0 0 0 0 -0 0</pose>
        <geometry>
          <box>
            <size>0.5 0.001 0.1</size>
          </box>
        </geometry>
      </collision>
    </link>
    <joint name="section_A_right_block_joint" type="fixed">
      <pose>0 0 0 0 0 0</pose>
      <child>section_A_right_block</child>
      <parent>section_A</parent>
    </joint>
    <static>0</static>
    <allow_auto_disable>1</allow_auto_disable>
  </model>
</sdf>
