<?xml version='1.0'?>
<sdf version='1.5'>
  <model name='simple_car'>
    <link name='chasis'>
      <pose frame=''>0 0 0.05 0 -0 0</pose>
      <inertial>
        <mass>1</mass>
        <inertia>
          <ixx>0.166667</ixx>
          <ixy>0</ixy>
          <ixz>0</ixz>
          <iyy>0.166667</iyy>
          <iyz>0</iyz>
          <izz>0.166667</izz>
        </inertia>
        <pose frame=''>0 0 0 0 -0 0</pose>
      </inertial>
      <self_collide>0</self_collide>
      <kinematic>0</kinematic>
      <gravity>1</gravity>
      <visual name='visual'>
        <geometry>
          <box>
            <size>0.3 0.2 0.1</size>
          </box>
        </geometry>
        <material>
          <script>
            <name>Gazebo/Grey</name>
            <uri>file://media/materials/scripts/gazebo.material</uri>
          </script>
          <ambient>0.3 0.3 0.3 1</ambient>
          <diffuse>0.7 0.7 0.7 1</diffuse>
          <specular>0.01 0.01 0.01 1</specular>
          <emissive>0 0 0 1</emissive>
          <shader type='vertex'>
            <normal_map>__default__</normal_map>
          </shader>
        </material>
        <pose frame=''>0 0 0 0 -0 0</pose>
        <cast_shadows>1</cast_shadows>
        <transparency>0</transparency>
      </visual>
      <collision name='collision'>
        <laser_retro>0</laser_retro>
        <max_contacts>10</max_contacts>
        <pose frame=''>0 0 0 0 -0 0</pose>
        <geometry>
          <box>
            <size>0.3 0.2 0.1</size>
          </box>
        </geometry>
      </collision>
    </link>

    <link name='drum_0'>
      <pose frame=''> 0.13 -0.12 0 1.5707 0 0</pose>
      <gravity>1</gravity>
      <self_collide>1</self_collide>
      <kinematic>0</kinematic>
      <inertial>
        <mass>1</mass>
        <inertia>
          <ixx>1</ixx>
          <ixy>0</ixy>
          <ixz>0</ixz>
          <iyy>1</iyy>
          <iyz>0</iyz>
          <izz>1</izz>
        </inertia>
      </inertial>
      <visual name='visual'>
        <pose frame=''>-0.0375 -0.0375 -0.034 0 -0 0</pose>
        <geometry>
          <mesh>
            <uri>model://track_drum/meshes/drum.STL</uri>
            <scale>0.001 0.001 0.001</scale>
          </mesh>
        </geometry>
        <material>
          <lighting>1</lighting>
          <script>
            <uri>file://media/materials/scripts/gazebo.material</uri>
            <name>Gazebo/Grey</name>
          </script>
          <ambient>0.3 0.3 0.3 1</ambient>
          <diffuse>0.7 0.7 0.7 1</diffuse>
          <specular>0.01 0.01 0.01 1</specular>
          <emissive>0 0 0 1</emissive>
          <shader type='vertex'>
            <normal_map>__default__</normal_map>
          </shader>
        </material>
        <cast_shadows>1</cast_shadows>
        <transparency>0</transparency>
      </visual>
      <collision name='collision'>
        <laser_retro>0</laser_retro>
        <max_contacts>20</max_contacts>
        <pose frame=''>-0.0375 -0.0375 -0.034 0 -0 0</pose>
        <geometry>
          <mesh>
            <uri>model://track_drum/meshes/drum.STL</uri>
            <scale>0.001 0.001 0.001</scale>
          </mesh>
        </geometry>
        <surface>
          <friction>
            <ode>
              <mu>1</mu>
              <mu2>1</mu2>
              <fdir1>0 0 0</fdir1>
              <slip1>0</slip1>
              <slip2>0</slip2>
            </ode>
          </friction>
          <bounce>
            <restitution_coefficient>0</restitution_coefficient>
            <threshold>1</threshold>
          </bounce>
          <contact>
            <collide_without_contact>0</collide_without_contact>
            <collide_without_contact_bitmask>1</collide_without_contact_bitmask>
            <collide_bitmask>1</collide_bitmask>
            <ode>
              <soft_cfm>0.1</soft_cfm>
              <soft_erp>0.2</soft_erp>
              <kp>1e+13</kp>
              <kd>1</kd>
              <max_vel>0.01</max_vel>
              <min_depth>0</min_depth>
            </ode>
            <bullet>
              <split_impulse>1</split_impulse>
              <split_impulse_penetration_threshold>-0.01</split_impulse_penetration_threshold>
              <soft_cfm>0</soft_cfm>
              <soft_erp>0.2</soft_erp>
              <kp>1e+13</kp>
              <kd>1</kd>
            </bullet>
          </contact>
        </surface>
      </collision>
    </link>
    
    <link name='drum_1'>
      <pose frame=''>-0.13 -0.12 0 1.5707 0 0</pose>
      <gravity>1</gravity>
      <self_collide>1</self_collide>
      <kinematic>0</kinematic>
      <inertial>
        <mass>1</mass>
        <inertia>
          <ixx>1</ixx>
          <ixy>0</ixy>
          <ixz>0</ixz>
          <iyy>1</iyy>
          <iyz>0</iyz>
          <izz>1</izz>
        </inertia>
      </inertial>
      <visual name='visual'>
        <pose frame=''>-0.0375 -0.0375 -0.034 0 -0 0</pose>
        <geometry>
          <mesh>
            <uri>model://track_drum/meshes/drum.STL</uri>
            <scale>0.001 0.001 0.001</scale>
          </mesh>
        </geometry>
        <material>
          <lighting>1</lighting>
          <script>
            <uri>file://media/materials/scripts/gazebo.material</uri>
            <name>Gazebo/Grey</name>
          </script>
          <ambient>0.3 0.3 0.3 1</ambient>
          <diffuse>0.7 0.7 0.7 1</diffuse>
          <specular>0.01 0.01 0.01 1</specular>
          <emissive>0 0 0 1</emissive>
          <shader type='vertex'>
            <normal_map>__default__</normal_map>
          </shader>
        </material>
        <cast_shadows>1</cast_shadows>
        <transparency>0</transparency>
      </visual>
      <collision name='collision'>
        <laser_retro>0</laser_retro>
        <max_contacts>20</max_contacts>
        <pose frame=''>-0.0375 -0.0375 -0.034 0 -0 0</pose>
        <geometry>
          <mesh>
            <uri>model://track_drum/meshes/drum.STL</uri>
            <scale>0.001 0.001 0.001</scale>
          </mesh>
        </geometry>
        <surface>
          <friction>
            <ode>
              <mu>1</mu>
              <mu2>1</mu2>
              <fdir1>0 0 0</fdir1>
              <slip1>0</slip1>
              <slip2>0</slip2>
            </ode>
          </friction>
          <bounce>
            <restitution_coefficient>0</restitution_coefficient>
            <threshold>1</threshold>
          </bounce>
          <contact>
            <collide_without_contact>0</collide_without_contact>
            <collide_without_contact_bitmask>1</collide_without_contact_bitmask>
            <collide_bitmask>1</collide_bitmask>
            <ode>
              <soft_cfm>0.1</soft_cfm>
              <soft_erp>0.2</soft_erp>
              <kp>1e+13</kp>
              <kd>1</kd>
              <max_vel>0.01</max_vel>
              <min_depth>0</min_depth>
            </ode>
            <bullet>
              <split_impulse>1</split_impulse>
              <split_impulse_penetration_threshold>-0.01</split_impulse_penetration_threshold>
              <soft_cfm>0</soft_cfm>
              <soft_erp>0.2</soft_erp>
              <kp>1e+13</kp>
              <kd>1</kd>
            </bullet>
          </contact>
        </surface>
      </collision>
    </link>

    <link name='drum_2'>
      <pose frame=''> 0.13  0.12 0 1.5707 0 3.14159</pose>
      <gravity>1</gravity>
      <self_collide>1</self_collide>
      <kinematic>0</kinematic>
      <inertial>
        <mass>1</mass>
        <inertia>
          <ixx>1</ixx>
          <ixy>0</ixy>
          <ixz>0</ixz>
          <iyy>1</iyy>
          <iyz>0</iyz>
          <izz>1</izz>
        </inertia>
      </inertial>
      <visual name='visual'>
        <pose frame=''>-0.0375 -0.0375 -0.034 0 -0 0</pose>
        <geometry>
          <mesh>
            <uri>model://track_drum/meshes/drum.STL</uri>
            <scale>0.001 0.001 0.001</scale>
          </mesh>
        </geometry>
        <material>
          <lighting>1</lighting>
          <script>
            <uri>file://media/materials/scripts/gazebo.material</uri>
            <name>Gazebo/Grey</name>
          </script>
          <ambient>0.3 0.3 0.3 1</ambient>
          <diffuse>0.7 0.7 0.7 1</diffuse>
          <specular>0.01 0.01 0.01 1</specular>
          <emissive>0 0 0 1</emissive>
          <shader type='vertex'>
            <normal_map>__default__</normal_map>
          </shader>
        </material>
        <cast_shadows>1</cast_shadows>
        <transparency>0</transparency>
      </visual>
      <collision name='collision'>
        <laser_retro>0</laser_retro>
        <max_contacts>20</max_contacts>
        <pose frame=''>-0.0375 -0.0375 -0.034 0 -0 0</pose>
        <geometry>
          <mesh>
            <uri>model://track_drum/meshes/drum.STL</uri>
            <scale>0.001 0.001 0.001</scale>
          </mesh>
        </geometry>
        <surface>
          <friction>
            <ode>
              <mu>1</mu>
              <mu2>1</mu2>
              <fdir1>0 0 0</fdir1>
              <slip1>0</slip1>
              <slip2>0</slip2>
            </ode>
          </friction>
          <bounce>
            <restitution_coefficient>0</restitution_coefficient>
            <threshold>1</threshold>
          </bounce>
          <contact>
            <collide_without_contact>0</collide_without_contact>
            <collide_without_contact_bitmask>1</collide_without_contact_bitmask>
            <collide_bitmask>1</collide_bitmask>
            <ode>
              <soft_cfm>0.1</soft_cfm>
              <soft_erp>0.2</soft_erp>
              <kp>1e+13</kp>
              <kd>1</kd>
              <max_vel>0.01</max_vel>
              <min_depth>0</min_depth>
            </ode>
            <bullet>
              <split_impulse>1</split_impulse>
              <split_impulse_penetration_threshold>-0.01</split_impulse_penetration_threshold>
              <soft_cfm>0</soft_cfm>
              <soft_erp>0.2</soft_erp>
              <kp>1e+13</kp>
              <kd>1</kd>
            </bullet>
          </contact>
        </surface>
      </collision>
    </link>

    <link name='drum_3'>
      <pose frame=''>-0.13  0.12 0 1.5707 0 3.14159</pose>
      <gravity>1</gravity>
      <self_collide>1</self_collide>
      <kinematic>0</kinematic>
      <inertial>
        <mass>1</mass>
        <inertia>
          <ixx>1</ixx>
          <ixy>0</ixy>
          <ixz>0</ixz>
          <iyy>1</iyy>
          <iyz>0</iyz>
          <izz>1</izz>
        </inertia>
      </inertial>
      <visual name='visual'>
        <pose frame=''>-0.0375 -0.0375 -0.034 0 -0 0</pose>
        <geometry>
          <mesh>
            <uri>model://track_drum/meshes/drum.STL</uri>
            <scale>0.001 0.001 0.001</scale>
          </mesh>
        </geometry>
        <material>
          <lighting>1</lighting>
          <script>
            <uri>file://media/materials/scripts/gazebo.material</uri>
            <name>Gazebo/Grey</name>
          </script>
          <ambient>0.3 0.3 0.3 1</ambient>
          <diffuse>0.7 0.7 0.7 1</diffuse>
          <specular>0.01 0.01 0.01 1</specular>
          <emissive>0 0 0 1</emissive>
          <shader type='vertex'>
            <normal_map>__default__</normal_map>
          </shader>
        </material>
        <cast_shadows>1</cast_shadows>
        <transparency>0</transparency>
      </visual>
      <collision name='collision'>
        <laser_retro>0</laser_retro>
        <max_contacts>20</max_contacts>
        <pose frame=''>-0.0375 -0.0375 -0.034 0 -0 0</pose>
        <geometry>
          <mesh>
            <uri>model://track_drum/meshes/drum.STL</uri>
            <scale>0.001 0.001 0.001</scale>
          </mesh>
        </geometry>
        <surface>
          <friction>
            <ode>
              <mu>1</mu>
              <mu2>1</mu2>
              <fdir1>0 0 0</fdir1>
              <slip1>0</slip1>
              <slip2>0</slip2>
            </ode>
          </friction>
          <bounce>
            <restitution_coefficient>0</restitution_coefficient>
            <threshold>1</threshold>
          </bounce>
          <contact>
            <collide_without_contact>0</collide_without_contact>
            <collide_without_contact_bitmask>1</collide_without_contact_bitmask>
            <collide_bitmask>1</collide_bitmask>
            <ode>
              <soft_cfm>0.1</soft_cfm>
              <soft_erp>0.2</soft_erp>
              <kp>1e+13</kp>
              <kd>1</kd>
              <max_vel>0.01</max_vel>
              <min_depth>0</min_depth>
            </ode>
            <bullet>
              <split_impulse>1</split_impulse>
              <split_impulse_penetration_threshold>-0.01</split_impulse_penetration_threshold>
              <soft_cfm>0</soft_cfm>
              <soft_erp>0.2</soft_erp>
              <kp>1e+13</kp>
              <kd>1</kd>
            </bullet>
          </contact>
        </surface>
      </collision>
    </link>

    <link name='left_block'>
      <pose frame=''>0 -0.155 0.02 0 -0 0</pose>
      <inertial>
        <mass>1</mass>
        <inertia>
          <ixx>0.166667</ixx>
          <ixy>0</ixy>
          <ixz>0</ixz>
          <iyy>0.166667</iyy>
          <iyz>0</iyz>
          <izz>0.166667</izz>
        </inertia>
        <pose frame=''>0 0 0 0 -0 0</pose>
      </inertial>
      <self_collide>0</self_collide>
      <kinematic>0</kinematic>
      <gravity>1</gravity>
      <visual name='visual'>
        <geometry>
          <box>
            <size>0.35 0.01 0.05</size>
          </box>
        </geometry>
        <material>
          <script>
            <name>Gazebo/Grey</name>
            <uri>file://media/materials/scripts/gazebo.material</uri>
          </script>
          <ambient>0.3 0.3 0.3 1</ambient>
          <diffuse>0.7 0.7 0.7 1</diffuse>
          <specular>0.01 0.01 0.01 1</specular>
          <emissive>0 0 0 1</emissive>
          <shader type='vertex'>
            <normal_map>__default__</normal_map>
          </shader>
        </material>
        <pose frame=''>0 0 0 0 -0 0</pose>
        <cast_shadows>1</cast_shadows>
        <transparency>0</transparency>
      </visual>
      <collision name='collision'>
        <laser_retro>0</laser_retro>
        <max_contacts>10</max_contacts>
        <pose frame=''>0 0 0 0 -0 0</pose>
        <geometry>
          <box>
            <size>0.35 0.01 0.05</size>
          </box>
        </geometry>
      </collision>
    </link>

    <link name='right_block'>
      <pose frame=''>0 0.155 0.02 0 -0 0</pose>
      <inertial>
        <mass>1</mass>
        <inertia>
          <ixx>0.166667</ixx>
          <ixy>0</ixy>
          <ixz>0</ixz>
          <iyy>0.166667</iyy>
          <iyz>0</iyz>
          <izz>0.166667</izz>
        </inertia>
        <pose frame=''>0 0 0 0 -0 0</pose>
      </inertial>
      <self_collide>0</self_collide>
      <kinematic>0</kinematic>
      <gravity>1</gravity>
      <visual name='visual'>
        <geometry>
          <box>
            <size>0.35 0.01 0.05</size>
          </box>
        </geometry>
        <material>
          <script>
            <name>Gazebo/Grey</name>
            <uri>file://media/materials/scripts/gazebo.material</uri>
          </script>
          <ambient>0.3 0.3 0.3 1</ambient>
          <diffuse>0.7 0.7 0.7 1</diffuse>
          <specular>0.01 0.01 0.01 1</specular>
          <emissive>0 0 0 1</emissive>
          <shader type='vertex'>
            <normal_map>__default__</normal_map>
          </shader>
        </material>
        <pose frame=''>0 0 0 0 -0 0</pose>
        <cast_shadows>1</cast_shadows>
        <transparency>0</transparency>
      </visual>
      <collision name='collision'>
        <laser_retro>0</laser_retro>
        <max_contacts>10</max_contacts>
        <pose frame=''>0 0 0 0 -0 0</pose>
        <geometry>
          <box>
            <size>0.35 0.01 0.05</size>
          </box>
        </geometry>
      </collision>
    </link>

    <joint name="left_block_joint" type="fixed">
      <pose>0 0 0 0 0 0</pose>
      <child>left_block</child>
      <parent>chasis</parent>
      <axis>
          <xyz>0 0 1</xyz>
      </axis>
    </joint>

    <joint name="right_block_joint" type="fixed">
      <pose>0 0 0 0 0 0</pose>
      <child>right_block</child>
      <parent>chasis</parent>
      <axis>
          <xyz>0 0 1</xyz>
      </axis>
    </joint>

    <joint name="joint_0" type="revolute">
      <pose>0 0 -0.015 0 0 0</pose>
      <child>drum_0</child>
      <parent>chasis</parent>
      <axis>
          <xyz>0 0 1</xyz>
      </axis>
    </joint>
    <joint name="joint_1" type="revolute">
      <pose>0 0 -0.015 0 0 0</pose>
      <child>drum_1</child>
      <parent>chasis</parent>
      <axis>
          <xyz>0 0 1</xyz>
      </axis>
    </joint>
    <joint name="joint_2" type="revolute">
      <pose>0 0 -0.015 0 0 0</pose>
      <child>drum_2</child>
      <parent>chasis</parent>
      <axis>
          <xyz>0 0 1</xyz>
      </axis>
    </joint>
    <joint name="joint_3" type="revolute">
      <pose>0 0 -0.015 0 0 0</pose>
      <child>drum_3</child>
      <parent>chasis</parent>
      <axis>
          <xyz>0 0 1</xyz>
      </axis>
    </joint>

    <static>0</static>
    <allow_auto_disable>1</allow_auto_disable>
    
    </model>
</sdf>
